Workbook

Sheet Verpflichtende Artikelmerkmale
A1: ID | B1: Kategorie Name | C1: Artikelmerkmal
A2: 33653 | B2: Auto & Motorrad: Teile [131090] > Autoteile & Zubehör [6030] > Anhängerkupplungen & Abschleppteile [180143] > Anhängerkupplungen & Komplettsätze [33653] | C2: AHK-Ausführung
A3: 33653 | B3: Auto & Motorrad: Teile [131090] > Autoteile & Zubehör [6030] > Anhängerkupplungen & Abschleppteile [180143] > Anhängerkupplungen & Komplettsätze [33653] | C3: E-Satz Typ
A4: 33653 | B4: Auto & Motorrad: Teile [131090] > Autoteile & Zubehör [6030] > Anhängerkupplungen & Abschleppteile [180143] > Anhängerkupplungen & Komplettsätze [33653] | C4: Produktart
A5: 33632 | B5: Auto & Motorrad: Teile [131090] > Autoteile & Zubehör [6030] > Auspuff- & Abgassysteme [33605] > Abgaskrümmer [33632] | C5: Im Lieferumfang enthalten
A6: 33632 | B6: Auto & Motorrad: Teile [131090] > Autoteile & Zubehör [6030] > Auspuff- & Abgassysteme [33605] > Abgaskrümmer [33632] | C6: Produktart
A7: 63276 | B7: Auto & Motorrad: Teile [131090] > Autoteile & Zubehör [6030] > Auspuff- & Abgassysteme [33605] > Lambdasonden & O2-Sensoren [63276] | C7: Sensorart
A8: 174028 | B8: Auto & Motorrad: Teile [131090] > Autoteile & Zubehör [6030] > Auspuff- & Abgassysteme [33605] > Partikelfilter [174028] | C8: Produktart
A9: 177699 | B9: Auto & Motorrad: Teile [131090] > Autoteile & Zubehör [6030] > Autoelektrik [33572] > Anlasser [177699] | C9: Produktart
A10: 179846 | B10: Auto & Motorrad: Teile [131090] > Autoteile & Zubehör [6030] > Autoelektrik [33572] > Batterien [179846] | C10: Produktart
A11: 177697 | B11: Auto & Motorrad: Teile [131090] > Autoteile & Zubehör [6030] > Autoelektrik [33572] > Lichtmaschinen & Generatoren [177697] | C11: Produktart
A12: 33710 | B12: Auto & Motorrad: Teile [131090] > Autoteile & Zubehör [6030] > Beleuchtung [33707] > Frontscheinwerfer [33710] | C12: Einbauposition
A13: 33710 | B13: Auto & Motorrad: Teile [131090] > Autoteile & Zubehör [6030] > Beleuchtung [33707] > Frontscheinwerfer [33710] | C13: Produktart
... A53: 179496 | B53: Auto & Motorrad: Teile [131090] > Öl, Pflege- & Schmiermittel [179487] > Motoröl [179496] | C53: Produktart

Sheet Werte
A1: ID | B1: Kategoriename | C1: Artikelmerkmal | D1: Beispielwerte
A2: 33566 | B2: =VLOOKUP(A2,'Verpflichtende Artikelmerkmale'!A:B,2,0) -> Auto & Motorrad: Teile [131090] > Autoteile & Zubehör [6030] > Bremsen & Bremsenteile [33559] > Hauptbremszylinder [33566] | C2: Produktart | D2: Hauptbremszylinder
A3: 33588 | B3: =VLOOKUP(A3,'Verpflichtende Artikelmerkmale'!A:B,2,0) -> Auto & Motorrad: Teile [131090] > Autoteile & Zubehör [6030] > Federung & Lenkung [33579] > Servopumpen [33588] | C3: Produktart | D3: Servopumpe
A4: 33602 | B4: =VLOOKUP(A4,'Verpflichtende Artikelmerkmale'!A:B,2,0) -> Auto & Motorrad: Teile [131090] > Autoteile & Zubehör [6030] > Motorkühlung [33599] > Wasserkühler [33602] | C4: Produktart | D4: Wasserkühler
A5: 33604 | B5: =VLOOKUP(A5,'Verpflichtende Artikelmerkmale'!A:B,2,0) -> Auto & Motorrad: Teile [131090] > Autoteile & Zubehör [6030] > Motorkühlung [33599] > Wasserpumpen [33604] | C5: Produktart | D5: Wasserpumpe
A6: 33632 | B6: =VLOOKUP(A6,'Verpflichtende Artikelmerkmale'!A:B,2,0) -> Auto & Motorrad: Teile [131090] > Autoteile & Zubehör [6030] > Auspuff- & Abgassysteme [33605] > Abgaskrümmer [33632] | C6: Produktart | D6: Abgaskrümmer
A7: 33632 | B7: =VLOOKUP(A7,'Verpflichtende Artikelmerkmale'!A:B,2,0) -> Auto & Motorrad: Teile [131090] > Autoteile & Zubehör [6030] > Auspuff- & Abgassysteme [33605] > Abgaskrümmer [33632] | C7: Im Lieferumfang enthalten | D7: Dichtung
A8: 33645 | B8: =VLOOKUP(A8,'Verpflichtende Artikelmerkmale'!A:B,2,0) -> Auto & Motorrad: Teile [131090] > Autoteile & Zubehör [6030] > Karosserie-, Anbauteile & Zubehör [33637] > Front- & Kühlergrills [33645] | C8: Produktart | D8: Kühlergrill
A9: 33653 | B9: Auto & Motorrad: Teile [131090] > Autoteile & Zubehör [6030] > Anhängerkupplungen & Abschleppteile [180143] > Anhängerkupplungen & Komplettsätze [33653] | C9: AHK-Ausführung | D9: Abnehmbar
A10: 33653 | B10: Auto & Motorrad: Teile [131090] > Autoteile & Zubehör [6030] > Anhängerkupplungen & Abschleppteile [180143] > Anhängerkupplungen & Komplettsätze [33653] | C10: Produktart | D10: Anhängerkup. & E-Satz komplett
A11: 33653 | B11: Auto & Motorrad: Teile [131090] > Autoteile & Zubehör [6030] > Anhängerkupplungen & Abschleppteile [180143] > Anhängerkupplungen & Komplettsätze [33653] | C11: AHK-Ausführung | D11: Elektrisch schwenkbar
A12: 33653 | B12: Auto & Motorrad: Teile [131090] > Autoteile & Zubehör [6030] > Anhängerkupplungen & Abschleppteile [180143] > Anhängerkupplungen & Komplettsätze [33653] | C12: E-Satz Typ | D12: Fahrzeugspezifisch
A13: 33653 | B13: Auto & Motorrad: Teile [131090] > Autoteile & Zubehör [6030] > Anhängerkupplungen & Abschleppteile [180143] > Anhängerkupplungen & Komplettsätze [33653] | C13: AHK-Ausführung | D13: Schwenkbar
A14: 33653 | B14: Auto & Motorrad: Teile [131090] > Autoteile & Zubehör [6030] > Anhängerkupplungen & Abschleppteile [180143] > Anhängerkupplungen & Komplettsätze [33653] | C14: AHK-Ausführung | D14: Starr
A15: 33653 | B15: Auto & Motorrad: Teile [131090] > Autoteile & Zubehör [6030] > Anhängerkupplungen & Abschleppteile [180143] > Anhängerkupplungen & Komplettsätze [33653] | C15: E-Satz Typ | D15: Universell
A16: 33659 | B16: =VLOOKUP(A16,'Verpflichtende Artikelmerkmale'!A:B,2,0) -> Auto & Motorrad: Teile [131090] > Autoteile & Zubehör [6030] > Luft- & Kraftstoffversorgung [33549] > Luftfilter [33659] | C16: Produktart | D16: Luftfilter
A17: 33660 | B17: =VLOOKUP(A17,'Verpflichtende Artikelmerkmale'!A:B,2,0) -> Auto & Motorrad: Teile [131090] > Autoteile & Zubehör [6030] > Luft- & Kraftstoffversorgung [33549] > Kraftstofffilter [33660] | C17: Produktart | D17: Kraftstofffilter
A18: 33709 | B18: =VLOOKUP(A18,'Verpflichtende Artikelmerkmale'!A:B,2,0) -> Auto & Motorrad: Teile [131090] > Autoteile & Zubehör [6030] > Beleuchtung [33707] > Nebelscheinwerfer [33709] | C18: Einbauposition | D18: Links
A19: 33709 | B19: =VLOOKUP(A19,'Verpflichtende Artikelmerkmale'!A:B,2,0) -> Auto & Motorrad: Teile [131090] > Autoteile & Zubehör [6030] > Beleuchtung [33707] > Nebelscheinwerfer [33709] | C19: Produktart | D19: Nebelscheinwerfer
A20: 33709 | B20: =VLOOKUP(A20,'Verpflichtende Artikelmerkmale'!A:B,2,0) -> Auto & Motorrad: Teile [131090] > Autoteile & Zubehör [6030] > Beleuchtung [33707] > Nebelscheinwerfer [33709] | C20: Einbauposition | D20: Rechts
A21: 33710 | B21: =VLOOKUP(A21,'Verpflichtende Artikelmerkmale'!A:B,2,0) -> Auto & Motorrad: Teile [131090] > Autoteile & Zubehör [6030] > Beleuchtung [33707] > Frontscheinwerfer [33710] | C21: Produktart | D21: Frontscheinwerfer
A22: 33710 | B22: =VLOOKUP(A22,'Verpflichtende Artikelmerkmale'!A:B,2,0) -> Auto & Motorrad: Teile [131090] > Autoteile & Zubehör [6030] > Beleuchtung [33707] > Frontscheinwerfer [33710] | C22: Einbauposition | D22: Links
A23: 33710 | B23: =VLOOKUP(A23,'Verpflichtende Artikelmerkmale'!A:B,2,0) -> Auto & Motorrad: Teile [131090] > Autoteile & Zubehör [6030] > Beleuchtung [33707] > Frontscheinwerfer [33710] | C23: Einbauposition | D23: Rechts
A24: 33716 | B24: =VLOOKUP(A24,'Verpflichtende Artikelmerkmale'!A:B,2,0) -> Auto & Motorrad: Teile [131090] > Autoteile & Zubehör [6030] > Beleuchtung [33707] > Rück- & Bremsleuchten [33716] | C24: Einbauposition | D24: Links
A25: 33716 | B25: =VLOOKUP(A25,'Verpflichtende Artikelmerkmale'!A:B,2,0) -> Auto & Motorrad: Teile [131090] > Autoteile & Zubehör [6030] > Beleuchtung [33707] > Rück- & Bremsleuchten [33716] | C25: Einbauposition | D25: Rechts
A26: 33716 | B26: =VLOOKUP(A26,'Verpflichtende Artikelmerkmale'!A:B,2,0) -> Auto & Motorrad: Teile [131090] > Autoteile & Zubehör [6030] > Beleuchtung [33707] > Rück- & Bremsleuchten [33716] | C26: Produktart | D26: Rück- & Bremsleuchte
A27: 38657 | B27: =VLOOKUP(A27,'Verpflichtende Artikelmerkmale'!A:B,2,0) -> Auto & Motorrad: Teile [131090] > Autoteile & Zubehör [6030] > Motoren & Motorenteile [33612] > Ölwannen [38657] | C27: Im Lieferumfang enthalten | D27: Dichtung
... A36: 57322 | B36: =VLOOKUP(A36,'Verpflichtende Artikelmerkmale'!A:B,2,0) -> Auto & Motorrad: Teile [131090] > Auto-Tuning & -Styling [107059] > Lichter & Leuchten [180425] > Rück- & Bremsleuchten [57322] | C36: Produktart | D36: Rück- & Bremsleuchte
A37: 57357 | B37: =VLOOKUP(A37,'Verpflichtende Artikelmerkmale'!A:B,2,0) -> Auto & Motorrad: Teile [131090] > Autoteile & Zubehör [6030] > Bremsen & Bremsenteile [33559] > Bremsbeläge [57357] | C37: Anzahl pro Packung | D37: 4
A38: 57357 | B38: =VLOOKUP(A38,'Verpflichtende Artikelmerkmale'!A:B,2,0) -> Auto & Motorrad: Teile [131090] > Autoteile & Zubehör [6030] > Bremsen & Bremsenteile [33559] > Bremsbeläge [57357] | C38: Anzahl pro Packung | D38: 8
A39: 57357 | B39: =VLOOKUP(A39,'Verpflichtende Artikelmerkmale'!A:B,2,0) -> Auto & Motorrad: Teile [131090] > Autoteile & Zubehör [6030] > Bremsen & Bremsenteile [33559] > Bremsbeläge [57357] | C39: Produktart | D39: Bremsbelagsatz
A40: 57357 | B40: =VLOOKUP(A40,'Verpflichtende Artikelmerkmale'!A:B,2,0) -> Auto & Motorrad: Teile [131090] > Autoteile & Zubehör [6030] > Bremsen & Bremsenteile [33559] > Bremsbeläge [57357] | C40: Einbauposition | D40: Hinten
A41: 57357 | B41: =VLOOKUP(A41,'Verpflichtende Artikelmerkmale'!A:B,2,0) -> Auto & Motorrad: Teile [131090] > Autoteile & Zubehör [6030] > Bremsen & Bremsenteile [33559] > Bremsbeläge [57357] | C41: Einbauposition | D41: Vorne
A42: 63276 | B42: =VLOOKUP(A42,'Verpflichtende Artikelmerkmale'!A:B,2,0) -> Auto & Motorrad: Teile [131090] > Autoteile & Zubehör [6030] > Auspuff- & Abgassysteme [33605] > Lambdasonden & O2-Sensoren [63276] | C42: Sensorart | D42: Lambdasonde
A43: 173511 | B43: =VLOOKUP(A43,'Verpflichtende Artikelmerkmale'!A:B,2,0) -> Auto & Motorrad: Teile [131090] > Autoteile & Zubehör [6030] > Bremsen & Bremsenteile [33559] > Bremsenkomplettsätze [173511] | C43: Im Lieferumfang enthalten | D43: Bremsbacke
A44: 173511 | B44: =VLOOKUP(A44,'Verpflichtende Artikelmerkmale'!A:B,2,0) -> Auto & Motorrad: Teile [131090] > Autoteile & Zubehör [6030] > Bremsen & Bremsenteile [33559] > Bremsenkomplettsätze [173511] | C44: Im Lieferumfang enthalten | D44: Bremsbacken
A45: 173511 | B45: =VLOOKUP(A45,'Verpflichtende Artikelmerkmale'!A:B,2,0) -> Auto & Motorrad: Teile [131090] > Autoteile & Zubehör [6030] > Bremsen & Bremsenteile [33559] > Bremsenkomplettsätze [173511] | C45: Im Lieferumfang enthalten | D45: Bremsbelag
A46: 173511 | B46: =VLOOKUP(A46,'Verpflichtende Artikelmerkmale'!A:B,2,0) -> Auto & Motorrad: Teile [131090] > Autoteile & Zubehör [6030] > Bremsen & Bremsenteile [33559] > Bremsenkomplettsätze [173511] | C46: Produktart | D46: Bremsenkomplettsatz
A47: 173511 | B47: =VLOOKUP(A47,'Verpflichtende Artikelmerkmale'!A:B,2,0) -> Auto & Motorrad: Teile [131090] > Autoteile & Zubehör [6030] > Bremsen & Bremsenteile [33559] > Bremsenkomplettsätze [173511] | C47: Im Lieferumfang enthalten | D47: Bremssattel
A48: 173511 | B48: =VLOOKUP(A48,'Verpflichtende Artikelmerkmale'!A:B,2,0) -> Auto & Motorrad: Teile [131090] > Autoteile & Zubehör [6030] > Bremsen & Bremsenteile [33559] > Bremsenkomplettsätze [173511] | C48: Im Lieferumfang enthalten | D48: Bremsscheibe
...
